[{
	"raw": {},
	"required": [
		"Filename",
		"Size"
	],
	"package": "python-zope.exceptions",
	"source": "zope.exceptions",
	"version": "4.0.6-1ubuntu2",
	"section": "universe/python",
	"priority": "extra",
	"architecture": "all",
	"depends": [
		"python-zope",
		"python (>= 2.7.1-0ubuntu2)",
		"python (<< 2.8)",
		"python-pkg-resources",
		"python-zope.interface"
	],
	"installedSize": 142,
	"maintainer": "Ubuntu Developers <ubuntu-devel-discuss@lists.ubuntu.com>",
	"description": "Zope exceptions for Python",
	"homepage": "http://pypi.python.org/pypi/zope.exceptions",
	"filename": "pool/universe/z/zope.exceptions/python-zope.exceptions_4.0.6-1ubuntu2_all.deb",
	"size": 15502,
	"md5": "a36c9ed23090b2aa76f7ed4ff66038b1",
	"sha1": "55d37d6feccb09f8834e05d9a286492811b32cb4",
	"sha256": "1519bc6b7c3079655445955efac9418ec8524ab23e226cf77c344aeb15c70125",
	"descriptionMd5": "fb63650b0843d0f5986f71aa80d2082d"
}]