[{
	"raw": {},
	"required": [
		"Filename",
		"Size"
	],
	"package": "python-zope.app.exception",
	"source": "zope.app.exception",
	"version": "3.6.3-0ubuntu2",
	"section": "universe/zope",
	"priority": "extra",
	"architecture": "all",
	"depends": [
		"python-pkg-resources",
		"python-zope",
		"python-zope.app",
		"python-zope.authentication",
		"python-zope.browser (>= 1.2)",
		"python-zope.browserpage (>= 3.11.0)",
		"python-zope.component",
		"python-zope.interface",
		"python-zope.publisher (>= 3.12)",
		"python-zope.security",
		"python2.7",
		"python (>= 2.7.1-0ubuntu2)",
		"python (<< 2.8)"
	],
	"suggests": [
		"python-zope.app.testing",
		"python-zope.app.zcmlfiles",
		"python-zope.login",
		"python-zope.password",
		"python-zope.securitypolicy"
	],
	"installedSize": 127,
	"maintainer": "Ubuntu Developers <ubuntu-devel-discuss@lists.ubuntu.com>",
	"description": "Zope 3 exception views",
	"filename": "pool/universe/z/zope.app.exception/python-zope.app.exception_3.6.3-0ubuntu2_all.deb",
	"size": 11368,
	"md5": "b3f925129faf960dc61c0543aafe275d",
	"sha1": "a4cc480fa14ae22d942faffeed59cb7dcccb25e9",
	"sha256": "1b37aecc413a44907d74557221159000f8b28f6dc95827f13eeefc6307f7a526",
	"descriptionMd5": "dde097202b6b0675233979e57658a7de"
}]