{
	"raw": {},
	"required": [
		"Filename",
		"Size"
	],
	"package": "python3-zope.exceptions",
	"source": "zope.exceptions",
	"version": "5.0.1-2",
	"section": "universe/zope",
	"priority": "extra",
	"architecture": "all",
	"depends": [
		"python3-pkg-resources",
		"python3-zope.interface",
		"python3:any"
	],
	"installedSize": 93,
	"maintainer": "Ubuntu Developers <ubuntu-devel-discuss@lists.ubuntu.com>",
	"description": "Zope exceptions for Python 3",
	"homepage": "https://github.com/zopefoundation/zope.exceptions",
	"filename": "pool/universe/z/zope.exceptions/python3-zope.exceptions_5.0.1-2_all.deb",
	"size": 16166,
	"md5": "db90488046100240d2ada46f02de9de3",
	"sha1": "7892d24d13e19268603c6c893e41914eedc2814e",
	"sha256": "5b72a7c1e11ef71dc59daa46f83465993aaf80b0a39d4fef75c2b79ebf411d69",
	"sha512": "25b031da93a55f2480cee8a09f419e0f9fc34c78e796ca4ec72831413bf98e972993e74cf5a4a2d8043e6634d0b0513e6ba92490b2a1383ac6022bc9458bb473",
	"descriptionMd5": "6659ed22b4d66ce3d4e50aa50de55f19"
}