{
	"raw": {},
	"required": [
		"Filename",
		"Size"
	],
	"package": "python3-zope.exceptions",
	"source": "zope.exceptions",
	"version": "4.0.6-1ubuntu2",
	"section": "universe/zope",
	"priority": "extra",
	"architecture": "all",
	"depends": [
		"python3-zope",
		"python3 (>= 3.2.3-3~)",
		"python3-pkg-resources",
		"python3-zope.interface"
	],
	"installedSize": 113,
	"maintainer": "Ubuntu Developers <ubuntu-devel-discuss@lists.ubuntu.com>",
	"description": "Zope exceptions for Python 3",
	"homepage": "http://pypi.python.org/pypi/zope.exceptions",
	"filename": "pool/universe/z/zope.exceptions/python3-zope.exceptions_4.0.6-1ubuntu2_all.deb",
	"size": 14778,
	"md5": "b34220d62f58e657515a691e356364ff",
	"sha1": "9de64c988c10ddf9c5678a44a1ea95cd6f3bda44",
	"sha256": "81a782a145e8493aac19cf661fbd53e77c269cfb51759f01b4c583db28776dcc",
	"descriptionMd5": "6659ed22b4d66ce3d4e50aa50de55f19"
}