{
	"raw": {},
	"required": [
		"Filename",
		"Size"
	],
	"package": "python3-zope.exceptions",
	"source": "zope.exceptions",
	"version": "5.2-1",
	"section": "universe/zope",
	"priority": "extra",
	"architecture": "all",
	"depends": [
		"python3-pkg-resources",
		"python3-zope.interface",
		"python3:any"
	],
	"installedSize": 95,
	"maintainer": "Ubuntu Developers <ubuntu-devel-discuss@lists.ubuntu.com>",
	"description": "Zope exceptions for Python 3",
	"homepage": "https://github.com/zopefoundation/zope.exceptions",
	"filename": "pool/universe/z/zope.exceptions/python3-zope.exceptions_5.2-1_all.deb",
	"size": 16810,
	"md5": "4c0e48035c85bbe50ac6f7e884689d4f",
	"sha1": "5591f3f8ff594b83c1f8b57724e3c07e43b6e683",
	"sha256": "2bd14cb7499edc0e43d28f97085e5eed44755437b9e74ec8c57497af8e431f79",
	"sha512": "c83d5b9e84464d2f1eac30c2b8bb1bab999fea7ecda19486f365ba9cb6d0890602835d964e6dd3116dcaf1a63d5e83f57639f4d07675d674f6a265bb42d162b0",
	"descriptionMd5": "6659ed22b4d66ce3d4e50aa50de55f19"
}